Workbook

Sheet Median & Ranges
A1: Species | B1: Metric | C1: Long_petiole_hair | D1: Short_petiole_hair | E1: Upper_lamina_hair | F1: Tooth_length | G1: Tooth_Width | H1: Flower_length | I1: Hypanthium_long | J1: Hypanthium_short | K1: Flower_width | L1: Stamen_length | M1: Style_length | N1: Pedicel_lengths | O1: Cymule_branches | P1: Thyrse_length | Q1: Petiole_length | R1: Leaf_width | S1: Leaf_length | T1: Capsule_width | U1: Capsule_length | V1: Cymule_flower_counts | W1: Whole_Cymule_lengths | X1: free_sepal_length | Y1: hypanthia_width_at_sepal_sinus
A2: AMERICANA | B2: Q1 | C2: {=_xlfn.QUARTILE.INC(_xlfn._xlws.FILTER(Americana!E$2:E1000, Americana!E$2:E1000<>""), 1)} -> 0 | D2: {=_xlfn.QUARTILE.INC(_xlfn._xlws.FILTER(Americana!F$2:F1000, Americana!F$2:F1000<>""), 1)} -> 0 | E2: {=_xlfn.QUARTILE.INC(_xlfn._xlws.FILTER(Americana!G$2:G1000, Americana!G$2:G1000<>""), 1)} -> 0 | F2: {=_xlfn.QUARTILE.INC(_xlfn._xlws.FILTER(Americana!H$2:H1000, Americana!H$2:H1000<>""), 1)} -> 4.167 | G2: {=_xlfn.QUARTILE.INC(_xlfn._xlws.FILTER(Americana!I$2:I1000, Americana!I$2:I1000<>""), 1)} -> 1.468 | H2: {=_xlfn.QUARTILE.INC(_xlfn._xlws.FILTER(Americana!J$2:J1000, Americana!J$2:J1000<>""), 1)} -> 3.19925 | I2: {=_xlfn.QUARTILE.INC(_xlfn._xlws.FILTER(Americana!K$2:K1000, Americana!K$2:K1000<>""), 1)} -> 1.35775 | J2: {=_xlfn.QUARTILE.INC(_xlfn._xlws.FILTER(Americana!L$2:L1000, Americana!L$2:L1000<>""), 1)} -> 1.1 | ... P2: {=_xlfn.QUARTILE.INC(_xlfn._xlws.FILTER(Americana!R$2:R1000, Americana!R$2:R1000<>""), 1)} -> 575.4465
A3: AMERICANA | B3: Q2 (median) | C3: {=_xlfn.QUARTILE.INC(_xlfn._xlws.FILTER(Americana!E$2:E1000, Americana!E$2:E1000<>""), 2)} -> 0 | D3: {=_xlfn.QUARTILE.INC(_xlfn._xlws.FILTER(Americana!F$2:F1000, Americana!F$2:F1000<>""), 2)} -> 0 | E3: {=_xlfn.QUARTILE.INC(_xlfn._xlws.FILTER(Americana!G$2:G1000, Americana!G$2:G1000<>""), 2)} -> 0 | F3: {=_xlfn.QUARTILE.INC(_xlfn._xlws.FILTER(Americana!H$2:H1000, Americana!H$2:H1000<>""), 2)} -> 5.341 | G3: {=_xlfn.QUARTILE.INC(_xlfn._xlws.FILTER(Americana!I$2:I1000, Americana!I$2:I1000<>""), 2)} -> 2.005 | H3: {=_xlfn.QUARTILE.INC(_xlfn._xlws.FILTER(Americana!J$2:J1000, Americana!J$2:J1000<>""), 2)} -> 3.552 | I3: {=_xlfn.QUARTILE.INC(_xlfn._xlws.FILTER(Americana!K$2:K1000, Americana!K$2:K1000<>""), 2)} -> 1.4935 | J3: {=_xlfn.QUARTILE.INC(_xlfn._xlws.FILTER(Americana!L$2:L1000, Americana!L$2:L1000<>""), 2)} -> 1.2395 | ... P3: {=_xlfn.QUARTILE.INC(_xlfn._xlws.FILTER(Americana!R$2:R1000, Americana!R$2:R1000<>""), 2)} -> 687.7755
A4: AMERICANA | B4: Q3 | C4: {=_xlfn.QUARTILE.INC(_xlfn._xlws.FILTER(Americana!E$2:E1000, Americana!E$2:E1000<>""), 3)} -> 0 | D4: {=_xlfn.QUARTILE.INC(_xlfn._xlws.FILTER(Americana!F$2:F1000, Americana!F$2:F1000<>""), 3)} -> 0 | E4: {=_xlfn.QUARTILE.INC(_xlfn._xlws.FILTER(Americana!G$2:G1000, Americana!G$2:G1000<>""), 3)} -> 0 | F4: {=_xlfn.QUARTILE.INC(_xlfn._xlws.FILTER(Americana!H$2:H1000, Americana!H$2:H1000<>""), 3)} -> 6.07075 | G4: {=_xlfn.QUARTILE.INC(_xlfn._xlws.FILTER(Americana!I$2:I1000, Americana!I$2:I1000<>""), 3)} -> 2.42175 | H4: {=_xlfn.QUARTILE.INC(_xlfn._xlws.FILTER(Americana!J$2:J1000, Americana!J$2:J1000<>""), 3)} -> 4.0565 | I4: {=_xlfn.QUARTILE.INC(_xlfn._xlws.FILTER(Americana!K$2:K1000, Americana!K$2:K1000<>""), 3)} -> 1.70225 | J4: {=_xlfn.QUARTILE.INC(_xlfn._xlws.FILTER(Americana!L$2:L1000, Americana!L$2:L1000<>""), 3)} -> 1.43475 | ... P4: {=_xlfn.QUARTILE.INC(_xlfn._xlws.FILTER(Americana!R$2:R1000, Americana!R$2:R1000<>""), 3)} -> 768.61675
A5: AMERICANA | B5: IQR | C5: {=_xlfn.QUARTILE.INC(_xlfn._xlws.FILTER(Americana!E$2:E1000, Americana!E$2:E1000<>""), 3) - _xlfn.QUARTILE.INC(_xlfn._xlws.FILTER(Americana!E$2:E1000, Americana!E$2:E1000<>""), 1)} -> 0 | D5: {=_xlfn.QUARTILE.INC(_xlfn._xlws.FILTER(Americana!F$2:F1000, Americana!F$2:F1000<>""), 3) - _xlfn.QUARTILE.INC(_xlfn._xlws.FILTER(Americana!F$2:F1000, Americana!F$2:F1000<>""), 1)} -> 0 | E5: {=_xlfn.QUARTILE.INC(_xlfn._xlws.FILTER(Americana!G$2:G1000, Americana!G$2:G1000<>""), 3) - _xlfn.QUARTILE.INC(_xlfn._xlws.FILTER(Americana!G$2:G1000, Americana!G$2:G1000<>""), 1)} -> 0 | F5: {=_xlfn.QUARTILE.INC(_xlfn._xlws.FILTER(Americana!H$2:H1000, Americana!H$2:H1000<>""), 3) - _xlfn.QUARTILE.INC(_xlfn._xlws.FILTER(Americana!H$2:H1000, Americana!H$2:H1000<>""), 1)} -> 1.90375 | G5: {=_xlfn.QUARTILE.INC(_xlfn._xlws.FILTER(Americana!I$2:I1000, Americana!I$2:I1000<>""), 3) - _xlfn.QUARTILE.INC(_xlfn._xlws.FILTER(Americana!I$2:I1000, Americana!I$2:I1000<>""), 1)} -> 0.95375 | H5: {=_xlfn.QUARTILE.INC(_xlfn._xlws.FILTER(Americana!J$2:J1000, Americana!J$2:J1000<>""), 3) - _xlfn.QUARTILE.INC(_xlfn._xlws.FILTER(Americana!J$2:J1000, Americana!J$2:J1000<>""), 1)} -> 0.85725 | I5: {=_xlfn.QUARTILE.INC(_xlfn._xlws.FILTER(Americana!K$2:K1000, Americana!K$2:K1000<>""), 3) - _xlfn.QUARTILE.INC(_xlfn._xlws.FILTER(Americana!K$2:K1000, Americana!K$2:K1000<>""), 1)} -> 0.3445 | J5: {=_xlfn.QUARTILE.INC(_xlfn._xlws.FILTER(Americana!L$2:L1000, Americana!L$2:L1000<>""), 3) - _xlfn.QUARTILE.INC(_xlfn._xlws.FILTER(Americana!L$2:L1000, Americana!L$2:L1000<>""), 1)} -> 0.33475 | ... P5: {=_xlfn.QUARTILE.INC(_xlfn._xlws.FILTER(Americana!R$2:R1000, Americana!R$2:R1000<>""), 3) - _xlfn.QUARTILE.INC(_xlfn._xlws.FILTER(Americana!R$2:R1000, Americana!R$2:R1000<>""), 1)} -> 193.17025
A6: AMERICANA | B6: Lower fence | C6: {=_xlfn.QUARTILE.INC(_xlfn._xlws.FILTER(Americana!E$2:E1000, Americana!E$2:E1000<>""), 1) - 1.5*(_xlfn.QUARTILE.INC(_xlfn._xlws.FILTER(Americana!E$2:E1000, Americana!E$2:E1000<>""), 3) - _xlfn.QUARTILE.INC(_xlfn._xlws.FILTER(Americana!E$2:E1000, Americana!E$2:E1000<>""), 1))} -> 0 | D6: {=_xlfn.QUARTILE.INC(_xlfn._xlws.FILTER(Americana!F$2:F1000, Americana!F$2:F1000<>""), 1) - 1.5*(_xlfn.QUARTILE.INC(_xlfn._xlws.FILTER(Americana!F$2:F1000, Americana!F$2:F1000<>""), 3) - _xlfn.QUARTILE.INC(_xlfn._xlws.FILTER(Americana!F$2:F1000, Americana!F$2:F1000<>""), 1))} -> 0 | E6: {=_xlfn.QUARTILE.INC(_xlfn._xlws.FILTER(Americana!G$2:G1000, Americana!G$2:G1000<>""), 1) - 1.5*(_xlfn.QUARTILE.INC(_xlfn._xlws.FILTER(Americana!G$2:G1000, Americana!G$2:G1000<>""), 3) - _xlfn.QUARTILE.INC(_xlfn._xlws.FILTER(Americana!G$2:G1000, Americana!G$2:G1000<>""), 1))} -> 0 | F6: {=_xlfn.QUARTILE.INC(_xlfn._xlws.FILTER(Americana!H$2:H1000, Americana!H$2:H1000<>""), 1) - 1.5*(_xlfn.QUARTILE.INC(_xlfn._xlws.FILTER(Americana!H$2:H1000, Americana!H$2:H1000<>""), 3) - _xlfn.QUARTILE.INC(_xlfn._xlws.FILTER(Americana!H$2:H1000, Americana!H$2:H1000<>""), 1))} -> 1.311375 | G6: {=_xlfn.QUARTILE.INC(_xlfn._xlws.FILTER(Americana!I$2:I1000, Americana!I$2:I1000<>""), 1) - 1.5*(_xlfn.QUARTILE.INC(_xlfn._xlws.FILTER(Americana!I$2:I1000, Americana!I$2:I1000<>""), 3) - _xlfn.QUARTILE.INC(_xlfn._xlws.FILTER(Americana!I$2:I1000, Americana!I$2:I1000<>""), 1))} -> 0.037375 | H6: {=_xlfn.QUARTILE.INC(_xlfn._xlws.FILTER(Americana!J$2:J1000, Americana!J$2:J1000<>""), 1) - 1.5*(_xlfn.QUARTILE.INC(_xlfn._xlws.FILTER(Americana!J$2:J1000, Americana!J$2:J1000<>""), 3) - _xlfn.QUARTILE.INC(_xlfn._xlws.FILTER(Americana!J$2:J1000, Americana!J$2:J1000<>""), 1))} -> 1.913375 | I6: {=_xlfn.QUARTILE.INC(_xlfn._xlws.FILTER(Americana!K$2:K1000, Americana!K$2:K1000<>""), 1) - 1.5*(_xlfn.QUARTILE.INC(_xlfn._xlws.FILTER(Americana!K$2:K1000, Americana!K$2:K1000<>""), 3) - _xlfn.QUARTILE.INC(_xlfn._xlws.FILTER(Americana!K$2:K1000, Americana!K$2:K1000<>""), 1))} -> 0.841 | J6: {=_xlfn.QUARTILE.INC(_xlfn._xlws.FILTER(Americana!L$2:L1000, Americana!L$2:L1000<>""), 1) - 1.5*(_xlfn.QUARTILE.INC(_xlfn._xlws.FILTER(Americana!L$2:L1000, Americana!L$2:L1000<>""), 3) - _xlfn.QUARTILE.INC(_xlfn._xlws.FILTER(Americana!L$2:L1000, Americana!L$2:L1000<>""), 1))} -> 0.597875 | ... P6: {=_xlfn.QUARTILE.INC(_xlfn._xlws.FILTER(Americana!R$2:R1000, Americana!R$2:R1000<>""), 1) - 1.5*(_xlfn.QUARTILE.INC(_xlfn._xlws.FILTER(Americana!R$2:R1000, Americana!R$2:R1000<>""), 3) - _xlfn.QUARTILE.INC(_xlfn._xlws.FILTER(Americana!R$2:R1000, Americana!R$2:R1000<>""), 1))} -> 285.69112
A7: AMERICANA | B7: Upper fence | C7: {=_xlfn.QUARTILE.INC(_xlfn._xlws.FILTER(Americana!E$2:E1000, Americana!E$2:E1000<>""), 3) + 1.5*(_xlfn.QUARTILE.INC(_xlfn._xlws.FILTER(Americana!E$2:E1000, Americana!E$2:E1000<>""), 3) - _xlfn.QUARTILE.INC(_xlfn._xlws.FILTER(Americana!E$2:E1000, Americana!E$2:E1000<>""), 1))} -> 0 | D7: {=_xlfn.QUARTILE.INC(_xlfn._xlws.FILTER(Americana!F$2:F1000, Americana!F$2:F1000<>""), 3) + 1.5*(_xlfn.QUARTILE.INC(_xlfn._xlws.FILTER(Americana!F$2:F1000, Americana!F$2:F1000<>""), 3) - _xlfn.QUARTILE.INC(_xlfn._xlws.FILTER(Americana!F$2:F1000, Americana!F$2:F1000<>""), 1))} -> 0 | E7: {=_xlfn.QUARTILE.INC(_xlfn._xlws.FILTER(Americana!G$2:G1000, Americana!G$2:G1000<>""), 3) + 1.5*(_xlfn.QUARTILE.INC(_xlfn._xlws.FILTER(Americana!G$2:G1000, Americana!G$2:G1000<>""), 3) - _xlfn.QUARTILE.INC(_xlfn._xlws.FILTER(Americana!G$2:G1000, Americana!G$2:G1000<>""), 1))} -> 0 | F7: {=_xlfn.QUARTILE.INC(_xlfn._xlws.FILTER(Americana!H$2:H1000, Americana!H$2:H1000<>""), 3) + 1.5*(_xlfn.QUARTILE.INC(_xlfn._xlws.FILTER(Americana!H$2:H1000, Americana!H$2:H1000<>""), 3) - _xlfn.QUARTILE.INC(_xlfn._xlws.FILTER(Americana!H$2:H1000, Americana!H$2:H1000<>""), 1))} -> 8.926375 | G7: {=_xlfn.QUARTILE.INC(_xlfn._xlws.FILTER(Americana!I$2:I1000, Americana!I$2:I1000<>""), 3) + 1.5*(_xlfn.QUARTILE.INC(_xlfn._xlws.FILTER(Americana!I$2:I1000, Americana!I$2:I1000<>""), 3) - _xlfn.QUARTILE.INC(_xlfn._xlws.FILTER(Americana!I$2:I1000, Americana!I$2:I1000<>""), 1))} -> 3.852375 | H7: {=_xlfn.QUARTILE.INC(_xlfn._xlws.FILTER(Americana!J$2:J1000, Americana!J$2:J1000<>""), 3) + 1.5*(_xlfn.QUARTILE.INC(_xlfn._xlws.FILTER(Americana!J$2:J1000, Americana!J$2:J1000<>""), 3) - _xlfn.QUARTILE.INC(_xlfn._xlws.FILTER(Americana!J$2:J1000, Americana!J$2:J1000<>""), 1))} -> 5.342375 | I7: {=_xlfn.QUARTILE.INC(_xlfn._xlws.FILTER(Americana!K$2:K1000, Americana!K$2:K1000<>""), 3) + 1.5*(_xlfn.QUARTILE.INC(_xlfn._xlws.FILTER(Americana!K$2:K1000, Americana!K$2:K1000<>""), 3) - _xlfn.QUARTILE.INC(_xlfn._xlws.FILTER(Americana!K$2:K1000, Americana!K$2:K1000<>""), 1))} -> 2.219 | J7: {=_xlfn.QUARTILE.INC(_xlfn._xlws.FILTER(Americana!L$2:L1000, Americana!L$2:L1000<>""), 3) + 1.5*(_xlfn.QUARTILE.INC(_xlfn._xlws.FILTER(Americana!L$2:L1000, Americana!L$2:L1000<>""), 3) - _xlfn.QUARTILE.INC(_xlfn._xlws.FILTER(Americana!L$2:L1000, Americana!L$2:L1000<>""), 1))} -> 1.936875 | ... P7: {=_xlfn.QUARTILE.INC(_xlfn._xlws.FILTER(Americana!R$2:R1000, Americana!R$2:R1000<>""), 3) + 1.5*(_xlfn.QUARTILE.INC(_xlfn._xlws.FILTER(Americana!R$2:R1000, Americana!R$2:R1000<>""), 3) - _xlfn.QUARTILE.INC(_xlfn._xlws.FILTER(Americana!R$2:R1000, Americana!R$2:R1000<>""), 1))} -> 1058.3721
A8: AMERICANA | B8: Absolute min | C8: {=MIN(_xlfn._xlws.FILTER(Americana!E$2:E1000, Americana!E$2:E1000<>""))} -> 0 | D8: {=MIN(_xlfn._xlws.FILTER(Americana!F$2:F1000, Americana!F$2:F1000<>""))} -> 0 | E8: {=MIN(_xlfn._xlws.FILTER(Americana!G$2:G1000, Americana!G$2:G1000<>""))} -> 0 | F8: {=MIN(_xlfn._xlws.FILTER(Americana!H$2:H1000, Americana!H$2:H1000<>""))} -> 2.147 | G8: {=MIN(_xlfn._xlws.FILTER(Americana!I$2:I1000, Americana!I$2:I1000<>""))} -> 0.378 | H8: {=MIN(_xlfn._xlws.FILTER(Americana!J$2:J1000, Americana!J$2:J1000<>""))} -> 2.299 | I8: {=MIN(_xlfn._xlws.FILTER(Americana!K$2:K1000, Americana!K$2:K1000<>""))} -> 0.778 | J8: {=MIN(_xlfn._xlws.FILTER(Americana!L$2:L1000, Americana!L$2:L1000<>""))} -> 0.375 | ... P8: {=MIN(_xlfn._xlws.FILTER(Americana!R$2:R1000, Americana!R$2:R1000<>""))} -> 436.43
A9: AMERICANA | B9: Absolute max | C9: {=MAX(_xlfn._xlws.FILTER(Americana!E$2:E1000, Americana!E$2:E1000<>""))} -> 2.874 | D9: {=MAX(_xlfn._xlws.FILTER(Americana!F$2:F1000, Americana!F$2:F1000<>""))} -> 0.504 | E9: {=MAX(_xlfn._xlws.FILTER(Americana!G$2:G1000, Americana!G$2:G1000<>""))} -> 0 | F9: {=MAX(_xlfn._xlws.FILTER(Americana!H$2:H1000, Americana!H$2:H1000<>""))} -> 8.625 | G9: {=MAX(_xlfn._xlws.FILTER(Americana!I$2:I1000, Americana!I$2:I1000<>""))} -> 3.299 | H9: {=MAX(_xlfn._xlws.FILTER(Americana!J$2:J1000, Americana!J$2:J1000<>""))} -> 4.997 | I9: {=MAX(_xlfn._xlws.FILTER(Americana!K$2:K1000, Americana!K$2:K1000<>""))} -> 1.999 | J9: {=MAX(_xlfn._xlws.FILTER(Americana!L$2:L1000, Americana!L$2:L1000<>""))} -> 1.865 | ... P9: {=MAX(_xlfn._xlws.FILTER(Americana!R$2:R1000, Americana!R$2:R1000<>""))} -> 945.758
A10: AMERICANA | B10: Full (absolute min) min–max (absolute max) mm | C10: ="(" & IF(MIN(Americana!E$2:E$1000)<_xlfn.QUARTILE.INC(Americana!E$2:E$1000,1)-1.5*(_xlfn.QUARTILE.INC(Americana!E$2:E$1000,3)-_xlfn.QUARTILE.INC(Americana!E$2:E$1000,1)),MIN(Americana!E$2:E$1000),"") & ") " & _xlfn.MINIFS(Americana!E$2:E$1000, Americana!E$2:E$1000, ">=" & _xlfn.QUARTILE.INC(Americana!E$2:E$1000,1)-1.5*(_xlfn.QUARTILE.INC(Americana!E$2:E$1000,3)-_xlfn.QUARTILE.INC(Americana!E$2:E$1000,1)), Americana!E$2:E$1000, "<=" & _xlfn.QUARTILE.INC(Americana!E$2:E$1000,3)+1.5*(_xlfn.QUARTILE.INC(Americana!E$2:E$1000,3)-_xlfn.QUARTILE.INC(Americana!E$2:E$1000,1))) & "–" & _xlfn.MAXIFS(Americana!E$2:E$1000, Americana!E$2:E$1000, ">=" & _xlfn.QUARTILE.INC(Americana!E$2:E$1000,1)-1.5*(_xlfn.QUARTILE.INC(Americana!E$2:E$1000,3)-_xlfn.QUARTILE.INC(Americana!E$2:E$1000,1)), Americana!E$2:E$1000, "<=" & _xlfn.QUARTILE.INC(Americana!E$2:E$1000,3)+1.5*(_xlfn.QUARTILE.INC(Americana!E$2:E$1000,3)-_xlfn.QUARTILE.INC(Americana!E$2:E$1000,1))) & " (" & IF(MAX(Americana!E$2:E$1000)>_xlfn.QUARTILE.INC(Americana!E$2:E$1000,3)+1.5*(_xlfn.QUARTILE.INC(Americana!E$2:E$1000,3)-_xlfn.QUARTILE.INC(Americana!E$2:E$1000,1)),MAX(Americana!E$2:E$1000),"") & ") mm" -> () 0–0 (2.874) mm | D10: ="(" & IF(MIN(Americana!F$2:F$1000)<_xlfn.QUARTILE.INC(Americana!F$2:F$1000,1)-1.5*(_xlfn.QUARTILE.INC(Americana!F$2:F$1000,3)-_xlfn.QUARTILE.INC(Americana!F$2:F$1000,1)),MIN(Americana!F$2:F$1000),"") & ") " & _xlfn.MINIFS(Americana!F$2:F$1000, Americana!F$2:F$1000, ">=" & _xlfn.QUARTILE.INC(Americana!F$2:F$1000,1)-1.5*(_xlfn.QUARTILE.INC(Americana!F$2:F$1000,3)-_xlfn.QUARTILE.INC(Americana!F$2:F$1000,1)), Americana!F$2:F$1000, "<=" & _xlfn.QUARTILE.INC(Americana!F$2:F$1000,3)+1.5*(_xlfn.QUARTILE.INC(Americana!F$2:F$1000,3)-_xlfn.QUARTILE.INC(Americana!F$2:F$1000,1))) & "–" & _xlfn.MAXIFS(Americana!F$2:F$1000, Americana!F$2:F$1000, ">=" & _xlfn.QUARTILE.INC(Americana!F$2:F$1000,1)-1.5*(_xlfn.QUARTILE.INC(Americana!F$2:F$1000,3)-_xlfn.QUARTILE.INC(Americana!F$2:F$1000,1)), Americana!F$2:F$1000, "<=" & _xlfn.QUARTILE.INC(Americana!F$2:F$1000,3)+1.5*(_xlfn.QUARTILE.INC(Americana!F$2:F$1000,3)-_xlfn.QUARTILE.INC(Americana!F$2:F$1000,1))) & " (" & IF(MAX(Americana!F$2:F$1000)>_xlfn.QUARTILE.INC(Americana!F$2:F$1000,3)+1.5*(_xlfn.QUARTILE.INC(Americana!F$2:F$1000,3)-_xlfn.QUARTILE.INC(Americana!F$2:F$1000,1)),MAX(Americana!F$2:F$1000),"") & ") mm" -> () 0–0 (0.504) mm | E10: ="(" & IF(MIN(Americana!G$2:G$1000)<_xlfn.QUARTILE.INC(Americana!G$2:G$1000,1)-1.5*(_xlfn.QUARTILE.INC(Americana!G$2:G$1000,3)-_xlfn.QUARTILE.INC(Americana!G$2:G$1000,1)),MIN(Americana!G$2:G$1000),"") & ") " & _xlfn.MINIFS(Americana!G$2:G$1000, Americana!G$2:G$1000, ">=" & _xlfn.QUARTILE.INC(Americana!G$2:G$1000,1)-1.5*(_xlfn.QUARTILE.INC(Americana!G$2:G$1000,3)-_xlfn.QUARTILE.INC(Americana!G$2:G$1000,1)), Americana!G$2:G$1000, "<=" & _xlfn.QUARTILE.INC(Americana!G$2:G$1000,3)+1.5*(_xlfn.QUARTILE.INC(Americana!G$2:G$1000,3)-_xlfn.QUARTILE.INC(Americana!G$2:G$1000,1))) & "–" & _xlfn.MAXIFS(Americana!G$2:G$1000, Americana!G$2:G$1000, ">=" & _xlfn.QUARTILE.INC(Americana!G$2:G$1000,1)-1.5*(_xlfn.QUARTILE.INC(Americana!G$2:G$1000,3)-_xlfn.QUARTILE.INC(Americana!G$2:G$1000,1)), Americana!G$2:G$1000, "<=" & _xlfn.QUARTILE.INC(Americana!G$2:G$1000,3)+1.5*(_xlfn.QUARTILE.INC(Americana!G$2:G$1000,3)-_xlfn.QUARTILE.INC(Americana!G$2:G$1000,1))) & " (" & IF(MAX(Americana!G$2:G$1000)>_xlfn.QUARTILE.INC(Americana!G$2:G$1000,3)+1.5*(_xlfn.QUARTILE.INC(Americana!G$2:G$1000,3)-_xlfn.QUARTILE.INC(Americana!G$2:G$1000,1)),MAX(Americana!G$2:G$1000),"") & ") mm" -> () 0–0 () mm | F10: ="(" & IF(MIN(Americana!H$2:H$1000)<_xlfn.QUARTILE.INC(Americana!H$2:H$1000,1)-1.5*(_xlfn.QUARTILE.INC(Americana!H$2:H$1000,3)-_xlfn.QUARTILE.INC(Americana!H$2:H$1000,1)),MIN(Americana!H$2:H$1000),"") & ") " & _xlfn.MINIFS(Americana!H$2:H$1000, Americana!H$2:H$1000, ">=" & _xlfn.QUARTILE.INC(Americana!H$2:H$1000,1)-1.5*(_xlfn.QUARTILE.INC(Americana!H$2:H$1000,3)-_xlfn.QUARTILE.INC(Americana!H$2:H$1000,1)), Americana!H$2:H$1000, "<=" & _xlfn.QUARTILE.INC(Americana!H$2:H$1000,3)+1.5*(_xlfn.QUARTILE.INC(Americana!H$2:H$1000,3)-_xlfn.QUARTILE.INC(Americana!H$2:H$1000,1))) & "–" & _xlfn.MAXIFS(Americana!H$2:H$1000, Americana!H$2:H$1000, ">=" & _xlfn.QUARTILE.INC(Americana!H$2:H$1000,1)-1.5*(_xlfn.QUARTILE.INC(Americana!H$2:H$1000,3)-_xlfn.QUARTILE.INC(Americana!H$2:H$1000,1)), Americana!H$2:H$1000, "<=" & _xlfn.QUARTILE.INC(Americana!H$2:H$1000,3)+1.5*(_xlfn.QUARTILE.INC(Americana!H$2:H$1000,3)-_xlfn.QUARTILE.INC(Americana!H$2:H$1000,1))) & " (" & IF(MAX(Americana!H$2:H$1000)>_xlfn.QUARTILE.INC(Americana!H$2:H$1000,3)+1.5*(_xlfn.QUARTILE.INC(Americana!H$2:H$1000,3)-_xlfn.QUARTILE.INC(Americana!H$2:H$1000,1)),MAX(Americana!H$2:H$1000),"") & ") mm" -> () 2.147–8.625 () mm | G10: ="(" & IF(MIN(Americana!I$2:I$1000)<_xlfn.QUARTILE.INC(Americana!I$2:I$1000,1)-1.5*(_xlfn.QUARTILE.INC(Americana!I$2:I$1000,3)-_xlfn.QUARTILE.INC(Americana!I$2:I$1000,1)),MIN(Americana!I$2:I$1000),"") & ") " & _xlfn.MINIFS(Americana!I$2:I$1000, Americana!I$2:I$1000, ">=" & _xlfn.QUARTILE.INC(Americana!I$2:I$1000,1)-1.5*(_xlfn.QUARTILE.INC(Americana!I$2:I$1000,3)-_xlfn.QUARTILE.INC(Americana!I$2:I$1000,1)), Americana!I$2:I$1000, "<=" & _xlfn.QUARTILE.INC(Americana!I$2:I$1000,3)+1.5*(_xlfn.QUARTILE.INC(Americana!I$2:I$1000,3)-_xlfn.QUARTILE.INC(Americana!I$2:I$1000,1))) & "–" & _xlfn.MAXIFS(Americana!I$2:I$1000, Americana!I$2:I$1000, ">=" & _xlfn.QUARTILE.INC(Americana!I$2:I$1000,1)-1.5*(_xlfn.QUARTILE.INC(Americana!I$2:I$1000,3)-_xlfn.QUARTILE.INC(Americana!I$2:I$1000,1)), Americana!I$2:I$1000, "<=" & _xlfn.QUARTILE.INC(Americana!I$2:I$1000,3)+1.5*(_xlfn.QUARTILE.INC(Americana!I$2:I$1000,3)-_xlfn.QUARTILE.INC(Americana!I$2:I$1000,1))) & " (" & IF(MAX(Americana!I$2:I$1000)>_xlfn.QUARTILE.INC(Americana!I$2:I$1000,3)+1.5*(_xlfn.QUARTILE.INC(Americana!I$2:I$1000,3)-_xlfn.QUARTILE.INC(Americana!I$2:I$1000,1)),MAX(Americana!I$2:I$1000),"") & ") mm" -> () 0.378–3.299 () mm | H10: ="(" & IF(MIN(Americana!J$2:J$1000)<_xlfn.QUARTILE.INC(Americana!J$2:J$1000,1)-1.5*(_xlfn.QUARTILE.INC(Americana!J$2:J$1000,3)-_xlfn.QUARTILE.INC(Americana!J$2:J$1000,1)),MIN(Americana!J$2:J$1000),"") & ") " & _xlfn.MINIFS(Americana!J$2:J$1000, Americana!J$2:J$1000, ">=" & _xlfn.QUARTILE.INC(Americana!J$2:J$1000,1)-1.5*(_xlfn.QUARTILE.INC(Americana!J$2:J$1000,3)-_xlfn.QUARTILE.INC(Americana!J$2:J$1000,1)), Americana!J$2:J$1000, "<=" & _xlfn.QUARTILE.INC(Americana!J$2:J$1000,3)+1.5*(_xlfn.QUARTILE.INC(Americana!J$2:J$1000,3)-_xlfn.QUARTILE.INC(Americana!J$2:J$1000,1))) & "–" & _xlfn.MAXIFS(Americana!J$2:J$1000, Americana!J$2:J$1000, ">=" & _xlfn.QUARTILE.INC(Americana!J$2:J$1000,1)-1.5*(_xlfn.QUARTILE.INC(Americana!J$2:J$1000,3)-_xlfn.QUARTILE.INC(Americana!J$2:J$1000,1)), Americana!J$2:J$1000, "<=" & _xlfn.QUARTILE.INC(Americana!J$2:J$1000,3)+1.5*(_xlfn.QUARTILE.INC(Americana!J$2:J$1000,3)-_xlfn.QUARTILE.INC(Americana!J$2:J$1000,1))) & " (" & IF(MAX(Americana!J$2:J$1000)>_xlfn.QUARTILE.INC(Americana!J$2:J$1000,3)+1.5*(_xlfn.QUARTILE.INC(Americana!J$2:J$1000,3)-_xlfn.QUARTILE.INC(Americana!J$2:J$1000,1)),MAX(Americana!J$2:J$1000),"") & ") mm" -> () 2.299–4.997 () mm | I10: ="(" & IF(MIN(Americana!K$2:K$1000)<_xlfn.QUARTILE.INC(Americana!K$2:K$1000,1)-1.5*(_xlfn.QUARTILE.INC(Americana!K$2:K$1000,3)-_xlfn.QUARTILE.INC(Americana!K$2:K$1000,1)),MIN(Americana!K$2:K$1000),"") & ") " & _xlfn.MINIFS(Americana!K$2:K$1000, Americana!K$2:K$1000, ">=" & _xlfn.QUARTILE.INC(Americana!K$2:K$1000,1)-1.5*(_xlfn.QUARTILE.INC(Americana!K$2:K$1000,3)-_xlfn.QUARTILE.INC(Americana!K$2:K$1000,1)), Americana!K$2:K$1000, "<=" & _xlfn.QUARTILE.INC(Americana!K$2:K$1000,3)+1.5*(_xlfn.QUARTILE.INC(Americana!K$2:K$1000,3)-_xlfn.QUARTILE.INC(Americana!K$2:K$1000,1))) & "–" & _xlfn.MAXIFS(Americana!K$2:K$1000, Americana!K$2:K$1000, ">=" & _xlfn.QUARTILE.INC(Americana!K$2:K$1000,1)-1.5*(_xlfn.QUARTILE.INC(Americana!K$2:K$1000,3)-_xlfn.QUARTILE.INC(Americana!K$2:K$1000,1)), Americana!K$2:K$1000, "<=" & _xlfn.QUARTILE.INC(Americana!K$2:K$1000,3)+1.5*(_xlfn.QUARTILE.INC(Americana!K$2:K$1000,3)-_xlfn.QUARTILE.INC(Americana!K$2:K$1000,1))) & " (" & IF(MAX(Americana!K$2:K$1000)>_xlfn.QUARTILE.INC(Americana!K$2:K$1000,3)+1.5*(_xlfn.QUARTILE.INC(Americana!K$2:K$1000,3)-_xlfn.QUARTILE.INC(Americana!K$2:K$1000,1)),MAX(Americana!K$2:K$1000),"") & ") mm" -> (0.778) 0.867–1.999 () mm | J10: ="(" & IF(MIN(Americana!L$2:L$1000)<_xlfn.QUARTILE.INC(Americana!L$2:L$1000,1)-1.5*(_xlfn.QUARTILE.INC(Americana!L$2:L$1000,3)-_xlfn.QUARTILE.INC(Americana!L$2:L$1000,1)),MIN(Americana!L$2:L$1000),"") & ") " & _xlfn.MINIFS(Americana!L$2:L$1000, Americana!L$2:L$1000, ">=" & _xlfn.QUARTILE.INC(Americana!L$2:L$1000,1)-1.5*(_xlfn.QUARTILE.INC(Americana!L$2:L$1000,3)-_xlfn.QUARTILE.INC(Americana!L$2:L$1000,1)), Americana!L$2:L$1000, "<=" & _xlfn.QUARTILE.INC(Americana!L$2:L$1000,3)+1.5*(_xlfn.QUARTILE.INC(Americana!L$2:L$1000,3)-_xlfn.QUARTILE.INC(Americana!L$2:L$1000,1))) & "–" & _xlfn.MAXIFS(Americana!L$2:L$1000, Americana!L$2:L$1000, ">=" & _xlfn.QUARTILE.INC(Americana!L$2:L$1000,1)-1.5*(_xlfn.QUARTILE.INC(Americana!L$2:L$1000,3)-_xlfn.QUARTILE.INC(Americana!L$2:L$1000,1)), Americana!L$2:L$1000, "<=" & _xlfn.QUARTILE.INC(Americana!L$2:L$1000,3)+1.5*(_xlfn.QUARTILE.INC(Americana!L$2:L$1000,3)-_xlfn.QUARTILE.INC(Americana!L$2:L$1000,1))) & " (" & IF(MAX(Americana!L$2:L$1000)>_xlfn.QUARTILE.INC(Americana!L$2:L$1000,3)+1.5*(_xlfn.QUARTILE.INC(Americana!L$2:L$1000,3)-_xlfn.QUARTILE.INC(Americana!L$2:L$1000,1)),MAX(Americana!L$2:L$1000),"") & ") mm" -> (0.375) 0.764–1.865 () mm | ... P10: ="(" & IF(MIN(Americana!R$2:R$1000)<_xlfn.QUARTILE.INC(Americana!R$2:R$1000,1)-1.5*(_xlfn.QUARTILE.INC(Americana!R$2:R$1000,3)-_xlfn.QUARTILE.INC(Americana!R$2:R$1000,1)),MIN(Americana!R$2:R$1000),"") & ") " & _xlfn.MINIFS(Americana!R$2:R$1000, Americana!R$2:R$1000, ">=" & _xlfn.QUARTILE.INC(Americana!R$2:R$1000,1)-1.5*(_xlfn.QUARTILE.INC(Americana!R$2:R$1000,3)-_xlfn.QUARTILE.INC(Americana!R$2:R$1000,1)), Americana!R$2:R$1000, "<=" & _xlfn.QUARTILE.INC(Americana!R$2:R$1000,3)+1.5*(_xlfn.QUARTILE.INC(Americana!R$2:R$1000,3)-_xlfn.QUARTILE.INC(Americana!R$2:R$1000,1))) & "–" & _xlfn.MAXIFS(Americana!R$2:R$1000, Americana!R$2:R$1000, ">=" & _xlfn.QUARTILE.INC(Americana!R$2:R$1000,1)-1.5*(_xlfn.QUARTILE.INC(Americana!R$2:R$1000,3)-_xlfn.QUARTILE.INC(Americana!R$2:R$1000,1)), Americana!R$2:R$1000, "<=" & _xlfn.QUARTILE.INC(Americana!R$2:R$1000,3)+1.5*(_xlfn.QUARTILE.INC(Americana!R$2:R$1000,3)-_xlfn.QUARTILE.INC(Americana!R$2:R$1000,1))) & " (" & IF(MAX(Americana!R$2:R$1000)>_xlfn.QUARTILE.INC(Americana!R$2:R$1000,3)+1.5*(_xlfn.QUARTILE.INC(Americana!R$2:R$1000,3)-_xlfn.QUARTILE.INC(Americana!R$2:R$1000,1)),MAX(Americana!R$2:R$1000),"") & ") mm" -> () 436.43–945.758 () mm
A11: BREVIPETALA Q1 | B11: Q1 | C11: {=_xlfn.QUARTILE.INC(_xlfn._xlws.FILTER(Brevipetala!E$2:E$1000, Brevipetala!E$2:E$1000<>""), 1)} -> 0 | D11: {=_xlfn.QUARTILE.INC(_xlfn._xlws.FILTER(Brevipetala!F$2:F$1000, Brevipetala!F$2:F$1000<>""), 1)} -> 0 | E11: {=_xlfn.QUARTILE.INC(_xlfn._xlws.FILTER(Brevipetala!G$2:G$1000, Brevipetala!G$2:G$1000<>""), 1)} -> 0 | F11: {=_xlfn.QUARTILE.INC(_xlfn._xlws.FILTER(Brevipetala!H$2:H$1000, Brevipetala!H$2:H$1000<>""), 1)} -> 3.742 | G11: {=_xlfn.QUARTILE.INC(_xlfn._xlws.FILTER(Brevipetala!I$2:I$1000, Brevipetala!I$2:I$1000<>""), 1)} -> 1.19275 | H11: {=_xlfn.QUARTILE.INC(_xlfn._xlws.FILTER(Brevipetala!J$2:J$1000, Brevipetala!J$2:J$1000<>""), 1)} -> 3.027 | I11: {=_xlfn.QUARTILE.INC(_xlfn._xlws.FILTER(Brevipetala!K$2:K$1000, Brevipetala!K$2:K$1000<>""), 1)} -> 0.9635 | J11: {=_xlfn.QUARTILE.INC(_xlfn._xlws.FILTER(Brevipetala!L$2:L$1000, Brevipetala!L$2:L$1000<>""), 1)} -> 0.753 | ... P11: {=_xlfn.QUARTILE.INC(_xlfn._xlws.FILTER(Brevipetala!R$2:R$1000, Brevipetala!R$2:R$1000<>""), 1)} -> 581.36725
A12: BREVIPETALA Q2 | B12: Q2 (median) | C12: {=_xlfn.QUARTILE.INC(_xlfn._xlws.FILTER(Brevipetala!E$2:E$1000, Brevipetala!E$2:E$1000<>""), 2)} -> 0 | D12: {=_xlfn.QUARTILE.INC(_xlfn._xlws.FILTER(Brevipetala!F$2:F$1000, Brevipetala!F$2:F$1000<>""), 2)} -> 0 | E12: {=_xlfn.QUARTILE.INC(_xlfn._xlws.FILTER(Brevipetala!G$2:G$1000, Brevipetala!G$2:G$1000<>""), 2)} -> 0 | F12: {=_xlfn.QUARTILE.INC(_xlfn._xlws.FILTER(Brevipetala!H$2:H$1000, Brevipetala!H$2:H$1000<>""), 2)} -> 4.9065 | G12: {=_xlfn.QUARTILE.INC(_xlfn._xlws.FILTER(Brevipetala!I$2:I$1000, Brevipetala!I$2:I$1000<>""), 2)} -> 1.5055 | H12: {=_xlfn.QUARTILE.INC(_xlfn._xlws.FILTER(Brevipetala!J$2:J$1000, Brevipetala!J$2:J$1000<>""), 2)} -> 3.7 | I12: {=_xlfn.QUARTILE.INC(_xlfn._xlws.FILTER(Brevipetala!K$2:K$1000, Brevipetala!K$2:K$1000<>""), 2)} -> 1.176 | J12: {=_xlfn.QUARTILE.INC(_xlfn._xlws.FILTER(Brevipetala!L$2:L$1000, Brevipetala!L$2:L$1000<>""), 2)} -> 0.9515 | ... P12: {=_xlfn.QUARTILE.INC(_xlfn._xlws.FILTER(Brevipetala!R$2:R$1000, Brevipetala!R$2:R$1000<>""), 2)} -> 694.712
A13: BREVIPETALA Q3 | B13: Q3 | C13: {=_xlfn.QUARTILE.INC(_xlfn._xlws.FILTER(Brevipetala!E$2:E$1000, Brevipetala!E$2:E$1000<>""), 3)} -> 0 | D13: {=_xlfn.QUARTILE.INC(_xlfn._xlws.FILTER(Brevipetala!F$2:F$1000, Brevipetala!F$2:F$1000<>""), 3)} -> 0 | E13: {=_xlfn.QUARTILE.INC(_xlfn._xlws.FILTER(Brevipetala!G$2:G$1000, Brevipetala!G$2:G$1000<>""), 3)} -> 0.723 | F13: {=_xlfn.QUARTILE.INC(_xlfn._xlws.FILTER(Brevipetala!H$2:H$1000, Brevipetala!H$2:H$1000<>""), 3)} -> 5.96375 | G13: {=_xlfn.QUARTILE.INC(_xlfn._xlws.FILTER(Brevipetala!I$2:I$1000, Brevipetala!I$2:I$1000<>""), 3)} -> 2.23 | H13: {=_xlfn.QUARTILE.INC(_xlfn._xlws.FILTER(Brevipetala!J$2:J$1000, Brevipetala!J$2:J$1000<>""), 3)} -> 4.095 | I13: {=_xlfn.QUARTILE.INC(_xlfn._xlws.FILTER(Brevipetala!K$2:K$1000, Brevipetala!K$2:K$1000<>""), 3)} -> 1.524 | J13: {=_xlfn.QUARTILE.INC(_xlfn._xlws.FILTER(Brevipetala!L$2:L$1000, Brevipetala!L$2:L$1000<>""), 3)} -> 1.26075 | ... P13: {=_xlfn.QUARTILE.INC(_xlfn._xlws.FILTER(Brevipetala!R$2:R$1000, Brevipetala!R$2:R$1000<>""), 3)} -> 783.85525
A14: BREVIPETALA IQR | B14: IQR | C14: {=_xlfn.QUARTILE.INC(_xlfn._xlws.FILTER(Brevipetala!E$2:E$1000, Brevipetala!E$2:E$1000<>""), 3) - _xlfn.QUARTILE.INC(_xlfn._xlws.FILTER(Brevipetala!E$2:E$1000, Brevipetala!E$2:E$1000<>""), 1)} -> 0 | D14: {=_xlfn.QUARTILE.INC(_xlfn._xlws.FILTER(Brevipetala!F$2:F$1000, Brevipetala!F$2:F$1000<>""), 3) - _xlfn.QUARTILE.INC(_xlfn._xlws.FILTER(Brevipetala!F$2:F$1000, Brevipetala!F$2:F$1000<>""), 1)} -> 0 | E14: {=_xlfn.QUARTILE.INC(_xlfn._xlws.FILTER(Brevipetala!G$2:G$1000, Brevipetala!G$2:G$1000<>""), 3) - _xlfn.QUARTILE.INC(_xlfn._xlws.FILTER(Brevipetala!G$2:G$1000, Brevipetala!G$2:G$1000<>""), 1)} -> 0.723 | F14: {=_xlfn.QUARTILE.INC(_xlfn._xlws.FILTER(Brevipetala!H$2:H$1000, Brevipetala!H$2:H$1000<>""), 3) - _xlfn.QUARTILE.INC(_xlfn._xlws.FILTER(Brevipetala!H$2:H$1000, Brevipetala!H$2:H$1000<>""), 1)} -> 2.22175 | G14: {=_xlfn.QUARTILE.INC(_xlfn._xlws.FILTER(Brevipetala!I$2:I$1000, Brevipetala!I$2:I$1000<>""), 3) - _xlfn.QUARTILE.INC(_xlfn._xlws.FILTER(Brevipetala!I$2:I$1000, Brevipetala!I$2:I$1000<>""), 1)} -> 1.03725 | H14: {=_xlfn.QUARTILE.INC(_xlfn._xlws.FILTER(Brevipetala!J$2:J$1000, Brevipetala!J$2:J$1000<>""), 3) - _xlfn.QUARTILE.INC(_xlfn._xlws.FILTER(Brevipetala!J$2:J$1000, Brevipetala!J$2:J$1000<>""), 1)} -> 1.068 | I14: {=_xlfn.QUARTILE.INC(_xlfn._xlws.FILTER(Brevipetala!K$2:K$1000, Brevipetala!K$2:K$1000<>""), 3) - _xlfn.QUARTILE.INC(_xlfn._xlws.FILTER(Brevipetala!K$2:K$1000, Brevipetala!K$2:K$1000<>""), 1)} -> 0.5605 | J14: {=_xlfn.QUARTILE.INC(_xlfn._xlws.FILTER(Brevipetala!L$2:L$1000, Brevipetala!L$2:L$1000<>""), 3) - _xlfn.QUARTILE.INC(_xlfn._xlws.FILTER(Brevipetala!L$2:L$1000, Brevipetala!L$2:L$1000<>""), 1)} -> 0.50775 | ... P14: {=_xlfn.QUARTILE.INC(_xlfn._xlws.FILTER(Brevipetala!R$2:R$1000, Brevipetala!R$2:R$1000<>""), 3) - _xlfn.QUARTILE.INC(_xlfn._xlws.FILTER(Brevipetala!R$2:R$1000, Brevipetala!R$2:R$1000<>""), 1)} -> 202.488
A15: BREVIPETALA lower bound outliers | B15: Lower fence | C15: {=_xlfn.QUARTILE.INC(_xlfn._xlws.FILTER(Brevipetala!E$2:E$1000, Brevipetala!E$2:E$1000<>""), 1) - 1.5*(_xlfn.QUARTILE.INC(_xlfn._xlws.FILTER(Brevipetala!E$2:E$1000, Brevipetala!E$2:E$1000<>""), 3) - _xlfn.QUARTILE.INC(_xlfn._xlws.FILTER(Brevipetala!E$2:E$1000, Brevipetala!E$2:E$1000<>""), 1))} -> 0 | D15: {=_xlfn.QUARTILE.INC(_xlfn._xlws.FILTER(Brevipetala!F$2:F$1000, Brevipetala!F$2:F$1000<>""), 1) - 1.5*(_xlfn.QUARTILE.INC(_xlfn._xlws.FILTER(Brevipetala!F$2:F$1000, Brevipetala!F$2:F$1000<>""), 3) - _xlfn.QUARTILE.INC(_xlfn._xlws.FILTER(Brevipetala!F$2:F$1000, Brevipetala!F$2:F$1000<>""), 1))} -> 0 | E15: {=_xlfn.QUARTILE.INC(_xlfn._xlws.FILTER(Brevipetala!G$2:G$1000, Brevipetala!G$2:G$1000<>""), 1) - 1.5*(_xlfn.QUARTILE.INC(_xlfn._xlws.FILTER(Brevipetala!G$2:G$1000, Brevipetala!G$2:G$1000<>""), 3) - _xlfn.QUARTILE.INC(_xlfn._xlws.FILTER(Brevipetala!G$2:G$1000, Brevipetala!G$2:G$1000<>""), 1))} -> -1.0845 | F15: {=_xlfn.QUARTILE.INC(_xlfn._xlws.FILTER(Brevipetala!H$2:H$1000, Brevipetala!H$2:H$1000<>""), 1) - 1.5*(_xlfn.QUARTILE.INC(_xlfn._xlws.FILTER(Brevipetala!H$2:H$1000, Brevipetala!H$2:H$1000<>""), 3) - _xlfn.QUARTILE.INC(_xlfn._xlws.FILTER(Brevipetala!H$2:H$1000, Brevipetala!H$2:H$1000<>""), 1))} -> 0.409375 | G15: {=_xlfn.QUARTILE.INC(_xlfn._xlws.FILTER(Brevipetala!I$2:I$1000, Brevipetala!I$2:I$1000<>""), 1) - 1.5*(_xlfn.QUARTILE.INC(_xlfn._xlws.FILTER(Brevipetala!I$2:I$1000, Brevipetala!I$2:I$1000<>""), 3) - _xlfn.QUARTILE.INC(_xlfn._xlws.FILTER(Brevipetala!I$2:I$1000, Brevipetala!I$2:I$1000<>""), 1))} -> -0.363125 | H15: {=_xlfn.QUARTILE.INC(_xlfn._xlws.FILTER(Brevipetala!J$2:J$1000, Brevipetala!J$2:J$1000<>""), 1) - 1.5*(_xlfn.QUARTILE.INC(_xlfn._xlws.FILTER(Brevipetala!J$2:J$1000, Brevipetala!J$2:J$1000<>""), 3) - _xlfn.QUARTILE.INC(_xlfn._xlws.FILTER(Brevipetala!J$2:J$1000, Brevipetala!J$2:J$1000<>""), 1))} -> 1.425 | I15: {=_xlfn.QUARTILE.INC(_xlfn._xlws.FILTER(Brevipetala!K$2:K$1000, Brevipetala!K$2:K$1000<>""), 1) - 1.5*(_xlfn.QUARTILE.INC(_xlfn._xlws.FILTER(Brevipetala!K$2:K$1000, Brevipetala!K$2:K$1000<>""), 3) - _xlfn.QUARTILE.INC(_xlfn._xlws.FILTER(Brevipetala!K$2:K$1000, Brevipetala!K$2:K$1000<>""), 1))} -> 0.12275 | J15: {=_xlfn.QUARTILE.INC(_xlfn._xlws.FILTER(Brevipetala!L$2:L$1000, Brevipetala!L$2:L$1000<>""), 1) - 1.5*(_xlfn.QUARTILE.INC(_xlfn._xlws.FILTER(Brevipetala!L$2:L$1000, Brevipetala!L$2:L$1000<>""), 3) - _xlfn.QUARTILE.INC(_xlfn._xlws.FILTER(Brevipetala!L$2:L$1000, Brevipetala!L$2:L$1000<>""), 1))} -> -0.008625 | ... P15: {=_xlfn.QUARTILE.INC(_xlfn._xlws.FILTER(Brevipetala!R$2:R$1000, Brevipetala!R$2:R$1000<>""), 1) - 1.5*(_xlfn.QUARTILE.INC(_xlfn._xlws.FILTER(Brevipetala!R$2:R$1000, Brevipetala!R$2:R$1000<>""), 3) - _xlfn.QUARTILE.INC(_xlfn._xlws.FILTER(Brevipetala!R$2:R$1000, Brevipetala!R$2:R$1000<>""), 1))} -> 277.63525
A16: BREVIPETALA upper bound outliers | B16: Upper fence | C16: {=_xlfn.QUARTILE.INC(_xlfn._xlws.FILTER(Brevipetala!E$2:E$1000, Brevipetala!E$2:E$1000<>""), 3) + 1.5*(_xlfn.QUARTILE.INC(_xlfn._xlws.FILTER(Brevipetala!E$2:E$1000, Brevipetala!E$2:E$1000<>""), 3) - _xlfn.QUARTILE.INC(_xlfn._xlws.FILTER(Brevipetala!E$2:E$1000, Brevipetala!E$2:E$1000<>""), 1))} -> 0 | D16: {=_xlfn.QUARTILE.INC(_xlfn._xlws.FILTER(Brevipetala!F$2:F$1000, Brevipetala!F$2:F$1000<>""), 3) + 1.5*(_xlfn.QUARTILE.INC(_xlfn._xlws.FILTER(Brevipetala!F$2:F$1000, Brevipetala!F$2:F$1000<>""), 3) - _xlfn.QUARTILE.INC(_xlfn._xlws.FILTER(Brevipetala!F$2:F$1000, Brevipetala!F$2:F$1000<>""), 1))} -> 0 | E16: {=_xlfn.QUARTILE.INC(_xlfn._xlws.FILTER(Brevipetala!G$2:G$1000, Brevipetala!G$2:G$1000<>""), 3) + 1.5*(_xlfn.QUARTILE.INC(_xlfn._xlws.FILTER(Brevipetala!G$2:G$1000, Brevipetala!G$2:G$1000<>""), 3) - _xlfn.QUARTILE.INC(_xlfn._xlws.FILTER(Brevipetala!G$2:G$1000, Brevipetala!G$2:G$1000<>""), 1))} -> 1.8075 | F16: {=_xlfn.QUARTILE.INC(_xlfn._xlws.FILTER(Brevipetala!H$2:H$1000, Brevipetala!H$2:H$1000<>""), 3) + 1.5*(_xlfn.QUARTILE.INC(_xlfn._xlws.FILTER(Brevipetala!H$2:H$1000, Brevipetala!H$2:H$1000<>""), 3) - _xlfn.QUARTILE.INC(_xlfn._xlws.FILTER(Brevipetala!H$2:H$1000, Brevipetala!H$2:H$1000<>""), 1))} -> 9.296375 | G16: {=_xlfn.QUARTILE.INC(_xlfn._xlws.FILTER(Brevipetala!I$2:I$1000, Brevipetala!I$2:I$1000<>""), 3) + 1.5*(_xlfn.QUARTILE.INC(_xlfn._xlws.FILTER(Brevipetala!I$2:I$1000, Brevipetala!I$2:I$1000<>""), 3) - _xlfn.QUARTILE.INC(_xlfn._xlws.FILTER(Brevipetala!I$2:I$1000, Brevipetala!I$2:I$1000<>""), 1))} -> 3.785875 | H16: {=_xlfn.QUARTILE.INC(_xlfn._xlws.FILTER(Brevipetala!J$2:J$1000, Brevipetala!J$2:J$1000<>""), 3) + 1.5*(_xlfn.QUARTILE.INC(_xlfn._xlws.FILTER(Brevipetala!J$2:J$1000, Brevipetala!J$2:J$1000<>""), 3) - _xlfn.QUARTILE.INC(_xlfn._xlws.FILTER(Brevipetala!J$2:J$1000, Brevipetala!J$2:J$1000<>""), 1))} -> 5.697 | I16: {=_xlfn.QUARTILE.INC(_xlfn._xlws.FILTER(Brevipetala!K$2:K$1000, Brevipetala!K$2:K$1000<>""), 3) + 1.5*(_xlfn.QUARTILE.INC(_xlfn._xlws.FILTER(Brevipetala!K$2:K$1000, Brevipetala!K$2:K$1000<>""), 3) - _xlfn.QUARTILE.INC(_xlfn._xlws.FILTER(Brevipetala!K$2:K$1000, Brevipetala!K$2:K$1000<>""), 1))} -> 2.36475 | J16: {=_xlfn.QUARTILE.INC(_xlfn._xlws.FILTER(Brevipetala!L$2:L$1000, Brevipetala!L$2:L$1000<>""), 3) + 1.5*(_xlfn.QUARTILE.INC(_xlfn._xlws.FILTER(Brevipetala!L$2:L$1000, Brevipetala!L$2:L$1000<>""), 3) - _xlfn.QUARTILE.INC(_xlfn._xlws.FILTER(Brevipetala!L$2:L$1000, Brevipetala!L$2:L$1000<>""), 1))} -> 2.022375 | ... P16: {=_xlfn.QUARTILE.INC(_xlfn._xlws.FILTER(Brevipetala!R$2:R$1000, Brevipetala!R$2:R$1000<>""), 3) + 1.5*(_xlfn.QUARTILE.INC(_xlfn._xlws.FILTER(Brevipetala!R$2:R$1000, Brevipetala!R$2:R$1000<>""), 3) - _xlfn.QUARTILE.INC(_xlfn._xlws.FILTER(Brevipetala!R$2:R$1000, Brevipetala!R$2:R$1000<>""), 1))} -> 1087.5872
A17: BREVIPETALA Min (excluding blanks) | B17: Absolute min | C17: {=MIN(_xlfn._xlws.FILTER(Brevipetala!E$2:E$1000, Brevipetala!E$2:E$1000<>""))} -> 0 | D17: {=MIN(_xlfn._xlws.FILTER(Brevipetala!F$2:F$1000, Brevipetala!F$2:F$1000<>""))} -> 0 | E17: {=MIN(_xlfn._xlws.FILTER(Brevipetala!G$2:G$1000, Brevipetala!G$2:G$1000<>""))} -> 0 | F17: {=MIN(_xlfn._xlws.FILTER(Brevipetala!H$2:H$1000, Brevipetala!H$2:H$1000<>""))} -> 1.645 | G17: {=MIN(_xlfn._xlws.FILTER(Brevipetala!I$2:I$1000, Brevipetala!I$2:I$1000<>""))} -> 0.269 | H17: {=MIN(_xlfn._xlws.FILTER(Brevipetala!J$2:J$1000, Brevipetala!J$2:J$1000<>""))} -> 2.01 | I17: {=MIN(_xlfn._xlws.FILTER(Brevipetala!K$2:K$1000, Brevipetala!K$2:K$1000<>""))} -> 0.423 | J17: {=MIN(_xlfn._xlws.FILTER(Brevipetala!L$2:L$1000, Brevipetala!L$2:L$1000<>""))} -> 0.289 | ... P17: {=MIN(_xlfn._xlws.FILTER(Brevipetala!R$2:R$1000, Brevipetala!R$2:R$1000<>""))} -> 238.652
A18: BREVIPETALA Max (excluding blanks) | B18: Absolute max
A19: BREVIPETALA Suggested bounds | B19: Full (absolute min) min–max (absolute max) mm | C19: {="(" & MIN(_xlfn._xlws.FILTER(Brevipetala!E$2:E1000,Brevipetala!E$2:E1000<>"")) & ") " & MIN(_xlfn._xlws.FILTER(Brevipetala!E$2:E1000,(Brevipetala!E$2:E1000<>"")*(Brevipetala!E$2:E1000>=_xlfn.QUARTILE.INC(_xlfn._xlws.FILTER(Brevipetala!E$2:E1000,Brevipetala!E$2:E1000<>""),1)-1.5*(_xlfn.QUARTILE.INC(_xlfn._xlws.FILTER(Brevipetala!E$2:E1000,Brevipetala!E$2:E1000<>""),3)-_xlfn.QUARTILE.INC(_xlfn._xlws.FILTER(Brevipetala!E$2:E1000,Brevipetala!E$2:E1000<>""),1))))) & "–" & MAX(_xlfn._xlws.FILTER(Brevipetala!E$2:E1000,(Brevipetala!E$2:E1000<>"")*(Brevipetala!E$2:E1000<=_xlfn.QUARTILE.INC(_xlfn._xlws.FILTER(Brevipetala!E$2:E1000,Brevipetala!E$2:E1000<>""),3)+1.5*(_xlfn.QUARTILE.INC(_xlfn._xlws.FILTER(Brevipetala!E$2:E1000,Brevipetala!E$2:E1000<>""),3)-_xlfn.QUARTILE.INC(_xlfn._xlws.FILTER(Brevipetala!E$2:E1000,Brevipetala!E$2:E1000<>""),1))))) & " (" & MAX(_xlfn._xlws.FILTER(Brevipetala!E$2:E1000,Brevipetala!E$2:E1000<>"")) & ") mm"} -> (0) 0–0 (0) mm | D19: {="(" & MIN(_xlfn._xlws.FILTER(Brevipetala!F$2:F1000,Brevipetala!F$2:F1000<>"")) & ") " & MIN(_xlfn._xlws.FILTER(Brevipetala!F$2:F1000,(Brevipetala!F$2:F1000<>"")*(Brevipetala!F$2:F1000>=_xlfn.QUARTILE.INC(_xlfn._xlws.FILTER(Brevipetala!F$2:F1000,Brevipetala!F$2:F1000<>""),1)-1.5*(_xlfn.QUARTILE.INC(_xlfn._xlws.FILTER(Brevipetala!F$2:F1000,Brevipetala!F$2:F1000<>""),3)-_xlfn.QUARTILE.INC(_xlfn._xlws.FILTER(Brevipetala!F$2:F1000,Brevipetala!F$2:F1000<>""),1))))) & "–" & MAX(_xlfn._xlws.FILTER(Brevipetala!F$2:F1000,(Brevipetala!F$2:F1000<>"")*(Brevipetala!F$2:F1000<=_xlfn.QUARTILE.INC(_xlfn._xlws.FILTER(Brevipetala!F$2:F1000,Brevipetala!F$2:F1000<>""),3)+1.5*(_xlfn.QUARTILE.INC(_xlfn._xlws.FILTER(Brevipetala!F$2:F1000,Brevipetala!F$2:F1000<>""),3)-_xlfn.QUARTILE.INC(_xlfn._xlws.FILTER(Brevipetala!F$2:F1000,Brevipetala!F$2:F1000<>""),1))))) & " (" & MAX(_xlfn._xlws.FILTER(Brevipetala!F$2:F1000,Brevipetala!F$2:F1000<>"")) & ") mm"} -> (0) 0–0 (0) mm | E19: {="(" & MIN(_xlfn._xlws.FILTER(Brevipetala!G$2:G1000,Brevipetala!G$2:G1000<>"")) & ") " & MIN(_xlfn._xlws.FILTER(Brevipetala!G$2:G1000,(Brevipetala!G$2:G1000<>"")*(Brevipetala!G$2:G1000>=_xlfn.QUARTILE.INC(_xlfn._xlws.FILTER(Brevipetala!G$2:G1000,Brevipetala!G$2:G1000<>""),1)-1.5*(_xlfn.QUARTILE.INC(_xlfn._xlws.FILTER(Brevipetala!G$2:G1000,Brevipetala!G$2:G1000<>""),3)-_xlfn.QUARTILE.INC(_xlfn._xlws.FILTER(Brevipetala!G$2:G1000,Brevipetala!G$2:G1000<>""),1))))) & "–" & MAX(_xlfn._xlws.FILTER(Brevipetala!G$2:G1000,(Brevipetala!G$2:G1000<>"")*(Brevipetala!G$2:G1000<=_xlfn.QUARTILE.INC(_xlfn._xlws.FILTER(Brevipetala!G$2:G1000,Brevipetala!G$2:G1000<>""),3)+1.5*(_xlfn.QUARTILE.INC(_xlfn._xlws.FILTER(Brevipetala!G$2:G1000,Brevipetala!G$2:G1000<>""),3)-_xlfn.QUARTILE.INC(_xlfn._xlws.FILTER(Brevipetala!G$2:G1000,Brevipetala!G$2:G1000<>""),1))))) & " (" & MAX(_xlfn._xlws.FILTER(Brevipetala!G$2:G1000,Brevipetala!G$2:G1000<>"")) & ") mm"} -> (0) 0–1.583 (1.583) mm | F19: {="(" & MIN(_xlfn._xlws.FILTER(Brevipetala!H$2:H1000,Brevipetala!H$2:H1000<>"")) & ") " & MIN(_xlfn._xlws.FILTER(Brevipetala!H$2:H1000,(Brevipetala!H$2:H1000<>"")*(Brevipetala!H$2:H1000>=_xlfn.QUARTILE.INC(_xlfn._xlws.FILTER(Brevipetala!H$2:H1000,Brevipetala!H$2:H1000<>""),1)-1.5*(_xlfn.QUARTILE.INC(_xlfn._xlws.FILTER(Brevipetala!H$2:H1000,Brevipetala!H$2:H1000<>""),3)-_xlfn.QUARTILE.INC(_xlfn._xlws.FILTER(Brevipetala!H$2:H1000,Brevipetala!H$2:H1000<>""),1))))) & "–" & MAX(_xlfn._xlws.FILTER(Brevipetala!H$2:H1000,(Brevipetala!H$2:H1000<>"")*(Brevipetala!H$2:H1000<=_xlfn.QUARTILE.INC(_xlfn._xlws.FILTER(Brevipetala!H$2:H1000,Brevipetala!H$2:H1000<>""),3)+1.5*(_xlfn.QUARTILE.INC(_xlfn._xlws.FILTER(Brevipetala!H$2:H1000,Brevipetala!H$2:H1000<>""),3)-_xlfn.QUARTILE.INC(_xlfn._xlws.FILTER(Brevipetala!H$2:H1000,Brevipetala!H$2:H1000<>""),1))))) & " (" & MAX(_xlfn._xlws.FILTER(Brevipetala!H$2:H1000,Brevipetala!H$2:H1000<>"")) & ") mm"} -> (1.645) 1.645–9.113 (10.68) mm | G19: {="(" & MIN(_xlfn._xlws.FILTER(Brevipetala!I$2:I1000,Brevipetala!I$2:I1000<>"")) & ") " & MIN(_xlfn._xlws.FILTER(Brevipetala!I$2:I1000,(Brevipetala!I$2:I1000<>"")*(Brevipetala!I$2:I1000>=_xlfn.QUARTILE.INC(_xlfn._xlws.FILTER(Brevipetala!I$2:I1000,Brevipetala!I$2:I1000<>""),1)-1.5*(_xlfn.QUARTILE.INC(_xlfn._xlws.FILTER(Brevipetala!I$2:I1000,Brevipetala!I$2:I1000<>""),3)-_xlfn.QUARTILE.INC(_xlfn._xlws.FILTER(Brevipetala!I$2:I1000,Brevipetala!I$2:I1000<>""),1))))) & "–" & MAX(_xlfn._xlws.FILTER(Brevipetala!I$2:I1000,(Brevipetala!I$2:I1000<>"")*(Brevipetala!I$2:I1000<=_xlfn.QUARTILE.INC(_xlfn._xlws.FILTER(Brevipetala!I$2:I1000,Brevipetala!I$2:I1000<>""),3)+1.5*(_xlfn.QUARTILE.INC(_xlfn._xlws.FILTER(Brevipetala!I$2:I1000,Brevipetala!I$2:I1000<>""),3)-_xlfn.QUARTILE.INC(_xlfn._xlws.FILTER(Brevipetala!I$2:I1000,Brevipetala!I$2:I1000<>""),1))))) & " (" & MAX(_xlfn._xlws.FILTER(Brevipetala!I$2:I1000,Brevipetala!I$2:I1000<>"")) & ") mm"} -> (0.269) 0.269–3.774 (6.49) mm | H19: {="(" & MIN(_xlfn._xlws.FILTER(Brevipetala!J$2:J1000,Brevipetala!J$2:J1000<>"")) & ") " & MIN(_xlfn._xlws.FILTER(Brevipetala!J$2:J1000,(Brevipetala!J$2:J1000<>"")*(Brevipetala!J$2:J1000>=_xlfn.QUARTILE.INC(_xlfn._xlws.FILTER(Brevipetala!J$2:J1000,Brevipetala!J$2:J1000<>""),1)-1.5*(_xlfn.QUARTILE.INC(_xlfn._xlws.FILTER(Brevipetala!J$2:J1000,Brevipetala!J$2:J1000<>""),3)-_xlfn.QUARTILE.INC(_xlfn._xlws.FILTER(Brevipetala!J$2:J1000,Brevipetala!J$2:J1000<>""),1))))) & "–" & MAX(_xlfn._xlws.FILTER(Brevipetala!J$2:J1000,(Brevipetala!J$2:J1000<>"")*(Brevipetala!J$2:J1000<=_xlfn.QUARTILE.INC(_xlfn._xlws.FILTER(Brevipetala!J$2:J1000,Brevipetala!J$2:J1000<>""),3)+1.5*(_xlfn.QUARTILE.INC(_xlfn._xlws.FILTER(Brevipetala!J$2:J1000,Brevipetala!J$2:J1000<>""),3)-_xlfn.QUARTILE.INC(_xlfn._xlws.FILTER(Brevipetala!J$2:J1000,Brevipetala!J$2:J1000<>""),1))))) & " (" & MAX(_xlfn._xlws.FILTER(Brevipetala!J$2:J1000,Brevipetala!J$2:J1000<>"")) & ") mm"} -> (2.01) 2.01–5.659 (5.659) mm | I19: {="(" & MIN(_xlfn._xlws.FILTER(Brevipetala!K$2:K1000,Brevipetala!K$2:K1000<>"")) & ") " & MIN(_xlfn._xlws.FILTER(Brevipetala!K$2:K1000,(Brevipetala!K$2:K1000<>"")*(Brevipetala!K$2:K1000>=_xlfn.QUARTILE.INC(_xlfn._xlws.FILTER(Brevipetala!K$2:K1000,Brevipetala!K$2:K1000<>""),1)-1.5*(_xlfn.QUARTILE.INC(_xlfn._xlws.FILTER(Brevipetala!K$2:K1000,Brevipetala!K$2:K1000<>""),3)-_xlfn.QUARTILE.INC(_xlfn._xlws.FILTER(Brevipetala!K$2:K1000,Brevipetala!K$2:K1000<>""),1))))) & "–" & MAX(_xlfn._xlws.FILTER(Brevipetala!K$2:K1000,(Brevipetala!K$2:K1000<>"")*(Brevipetala!K$2:K1000<=_xlfn.QUARTILE.INC(_xlfn._xlws.FILTER(Brevipetala!K$2:K1000,Brevipetala!K$2:K1000<>""),3)+1.5*(_xlfn.QUARTILE.INC(_xlfn._xlws.FILTER(Brevipetala!K$2:K1000,Brevipetala!K$2:K1000<>""),3)-_xlfn.QUARTILE.INC(_xlfn._xlws.FILTER(Brevipetala!K$2:K1000,Brevipetala!K$2:K1000<>""),1))))) & " (" & MAX(_xlfn._xlws.FILTER(Brevipetala!K$2:K1000,Brevipetala!K$2:K1000<>"")) & ") mm"} -> (0.423) 0.423–2.309 (2.309) mm | J19: {="(" & MIN(_xlfn._xlws.FILTER(Brevipetala!L$2:L1000,Brevipetala!L$2:L1000<>"")) & ") " & MIN(_xlfn._xlws.FILTER(Brevipetala!L$2:L1000,(Brevipetala!L$2:L1000<>"")*(Brevipetala!L$2:L1000>=_xlfn.QUARTILE.INC(_xlfn._xlws.FILTER(Brevipetala!L$2:L1000,Brevipetala!L$2:L1000<>""),1)-1.5*(_xlfn.QUARTILE.INC(_xlfn._xlws.FILTER(Brevipetala!L$2:L1000,Brevipetala!L$2:L1000<>""),3)-_xlfn.QUARTILE.INC(_xlfn._xlws.FILTER(Brevipetala!L$2:L1000,Brevipetala!L$2:L1000<>""),1))))) & "–" & MAX(_xlfn._xlws.FILTER(Brevipetala!L$2:L1000,(Brevipetala!L$2:L1000<>"")*(Brevipetala!L$2:L1000<=_xlfn.QUARTILE.INC(_xlfn._xlws.FILTER(Brevipetala!L$2:L1000,Brevipetala!L$2:L1000<>""),3)+1.5*(_xlfn.QUARTILE.INC(_xlfn._xlws.FILTER(Brevipetala!L$2:L1000,Brevipetala!L$2:L1000<>""),3)-_xlfn.QUARTILE.INC(_xlfn._xlws.FILTER(Brevipetala!L$2:L1000,Brevipetala!L$2:L1000<>""),1))))) & " (" & MAX(_xlfn._xlws.FILTER(Brevipetala!L$2:L1000,Brevipetala!L$2:L1000<>"")) & ") mm"} -> (0.289) 0.289–1.979 (1.979) mm | ... P19: {="(" & MIN(_xlfn._xlws.FILTER(Brevipetala!R$2:R1000,Brevipetala!R$2:R1000<>"")) & ") " & MIN(_xlfn._xlws.FILTER(Brevipetala!R$2:R1000,(Brevipetala!R$2:R1000<>"")*(Brevipetala!R$2:R1000>=_xlfn.QUARTILE.INC(_xlfn._xlws.FILTER(Brevipetala!R$2:R1000,Brevipetala!R$2:R1000<>""),1)-1.5*(_xlfn.QUARTILE.INC(_xlfn._xlws.FILTER(Brevipetala!R$2:R1000,Brevipetala!R$2:R1000<>""),3)-_xlfn.QUARTILE.INC(_xlfn._xlws.FILTER(Brevipetala!R$2:R1000,Brevipetala!R$2:R1000<>""),1))))) & "–" & MAX(_xlfn._xlws.FILTER(Brevipetala!R$2:R1000,(Brevipetala!R$2:R1000<>"")*(Brevipetala!R$2:R1000<=_xlfn.QUARTILE.INC(_xlfn._xlws.FILTER(Brevipetala!R$2:R1000,Brevipetala!R$2:R1000<>""),3)+1.5*(_xlfn.QUARTILE.INC(_xlfn._xlws.FILTER(Brevipetala!R$2:R1000,Brevipetala!R$2:R1000<>""),3)-_xlfn.QUARTILE.INC(_xlfn._xlws.FILTER(Brevipetala!R$2:R1000,Brevipetala!R$2:R1000<>""),1))))) & " (" & MAX(_xlfn._xlws.FILTER(Brevipetala!R$2:R1000,Brevipetala!R$2:R1000<>"")) & ") mm"} -> (238.652) 322.12–1012.704 (1012.704) mm
A20: CALYCOSA Q1 | B20: Q1 | C20: {=_xlfn.QUARTILE.INC(_xlfn._xlws.FILTER(Calycosa!E$2:E1000, Calycosa!E$2:E1000<>""), 1)} -> 0 | D20: {=_xlfn.QUARTILE.INC(_xlfn._xlws.FILTER(Calycosa!F$2:F1000, Calycosa!F$2:F1000<>""), 1)} -> 0 | E20: {=_xlfn.QUARTILE.INC(_xlfn._xlws.FILTER(Calycosa!G$2:G1000, Calycosa!G$2:G1000<>""), 1)} -> 0 | F20: {=_xlfn.QUARTILE.INC(_xlfn._xlws.FILTER(Calycosa!H$2:H1000, Calycosa!H$2:H1000<>""), 1)} -> 3.755 | G20: {=_xlfn.QUARTILE.INC(_xlfn._xlws.FILTER(Calycosa!I$2:I1000, Calycosa!I$2:I1000<>""), 1)} -> 1.14025 | H20: {=_xlfn.QUARTILE.INC(_xlfn._xlws.FILTER(Calycosa!J$2:J1000, Calycosa!J$2:J1000<>""), 1)} -> 2.676 | I20: {=_xlfn.QUARTILE.INC(_xlfn._xlws.FILTER(Calycosa!K$2:K1000, Calycosa!K$2:K1000<>""), 1)} -> 0.864 | J20: {=_xlfn.QUARTILE.INC(_xlfn._xlws.FILTER(Calycosa!L$2:L1000, Calycosa!L$2:L1000<>""), 1)} -> 0.68925 | ... P20: {=_xlfn.QUARTILE.INC(_xlfn._xlws.FILTER(Calycosa!R$2:R1000, Calycosa!R$2:R1000<>""), 1)} -> 599.278
A21: CALYCOSA Q2 | B21: Q2 (median) | C21: {=_xlfn.QUARTILE.INC(_xlfn._xlws.FILTER(Calycosa!E$2:E1000, Calycosa!E$2:E1000<>""), 2)} -> 0 | D21: {=_xlfn.QUARTILE.INC(_xlfn._xlws.FILTER(Calycosa!F$2:F1000, Calycosa!F$2:F1000<>""), 2)} -> 0 | E21: {=_xlfn.QUARTILE.INC(_xlfn._xlws.FILTER(Calycosa!G$2:G1000, Calycosa!G$2:G1000<>""), 2)} -> 0 | F21: {=_xlfn.QUARTILE.INC(_xlfn._xlws.FILTER(Calycosa!H$2:H1000, Calycosa!H$2:H1000<>""), 2)} -> 4.2975 | G21: {=_xlfn.QUARTILE.INC(_xlfn._xlws.FILTER(Calycosa!I$2:I1000, Calycosa!I$2:I1000<>""), 2)} -> 1.537 | H21: {=_xlfn.QUARTILE.INC(_xlfn._xlws.FILTER(Calycosa!J$2:J1000, Calycosa!J$2:J1000<>""), 2)} -> 2.916 | I21: {=_xlfn.QUARTILE.INC(_xlfn._xlws.FILTER(Calycosa!K$2:K1000, Calycosa!K$2:K1000<>""), 2)} -> 1.066 | J21: {=_xlfn.QUARTILE.INC(_xlfn._xlws.FILTER(Calycosa!L$2:L1000, Calycosa!L$2:L1000<>""), 2)} -> 0.89 | ... P21: {=_xlfn.QUARTILE.INC(_xlfn._xlws.FILTER(Calycosa!R$2:R1000, Calycosa!R$2:R1000<>""), 2)} -> 673.393
A22: CALYCOSA Q3 | B22: Q3 | C22: {=_xlfn.QUARTILE.INC(_xlfn._xlws.FILTER(Calycosa!E$2:E1000, Calycosa!E$2:E1000<>""), 3)} -> 0 | D22: {=_xlfn.QUARTILE.INC(_xlfn._xlws.FILTER(Calycosa!F$2:F1000, Calycosa!F$2:F1000<>""), 3)} -> 0 | E22: {=_xlfn.QUARTILE.INC(_xlfn._xlws.FILTER(Calycosa!G$2:G1000, Calycosa!G$2:G1000<>""), 3)} -> 0 | F22: {=_xlfn.QUARTILE.INC(_xlfn._xlws.FILTER(Calycosa!H$2:H1000, Calycosa!H$2:H1000<>""), 3)} -> 4.82875 | G22: {=_xlfn.QUARTILE.INC(_xlfn._xlws.FILTER(Calycosa!I$2:I1000, Calycosa!I$2:I1000<>""), 3)} -> 1.837 | H22: {=_xlfn.QUARTILE.INC(_xlfn._xlws.FILTER(Calycosa!J$2:J1000, Calycosa!J$2:J1000<>""), 3)} -> 3.39 | I22: {=_xlfn.QUARTILE.INC(_xlfn._xlws.FILTER(Calycosa!K$2:K1000, Calycosa!K$2:K1000<>""), 3)} -> 1.269 | J22: {=_xlfn.QUARTILE.INC(_xlfn._xlws.FILTER(Calycosa!L$2:L1000, Calycosa!L$2:L1000<>""), 3)} -> 1.15175 | ... P22: {=_xlfn.QUARTILE.INC(_xlfn._xlws.FILTER(Calycosa!R$2:R1000, Calycosa!R$2:R1000<>""), 3)} -> 816.576
A23: CALYCOSA IQR | B23: IQR | C23: {=_xlfn.QUARTILE.INC(_xlfn._xlws.FILTER(Calycosa!E$2:E1000, Calycosa!E$2:E1000<>""), 3) - _xlfn.QUARTILE.INC(_xlfn._xlws.FILTER(Calycosa!E$2:E1000, Calycosa!E$2:E1000<>""), 1)} -> 0 | D23: {=_xlfn.QUARTILE.INC(_xlfn._xlws.FILTER(Calycosa!F$2:F1000, Calycosa!F$2:F1000<>""), 3) - _xlfn.QUARTILE.INC(_xlfn._xlws.FILTER(Calycosa!F$2:F1000, Calycosa!F$2:F1000<>""), 1)} -> 0 | E23: {=_xlfn.QUARTILE.INC(_xlfn._xlws.FILTER(Calycosa!G$2:G1000, Calycosa!G$2:G1000<>""), 3) - _xlfn.QUARTILE.INC(_xlfn._xlws.FILTER(Calycosa!G$2:G1000, Calycosa!G$2:G1000<>""), 1)} -> 0 | F23: {=_xlfn.QUARTILE.INC(_xlfn._xlws.FILTER(Calycosa!H$2:H1000, Calycosa!H$2:H1000<>""), 3) - _xlfn.QUARTILE.INC(_xlfn._xlws.FILTER(Calycosa!H$2:H1000, Calycosa!H$2:H1000<>""), 1)} -> 1.07375 | G23: {=_xlfn.QUARTILE.INC(_xlfn._xlws.FILTER(Calycosa!I$2:I1000, Calycosa!I$2:I1000<>""), 3) - _xlfn.QUARTILE.INC(_xlfn._xlws.FILTER(Calycosa!I$2:I1000, Calycosa!I$2:I1000<>""), 1)} -> 0.69675 | H23: {=_xlfn.QUARTILE.INC(_xlfn._xlws.FILTER(Calycosa!J$2:J1000, Calycosa!J$2:J1000<>""), 3) - _xlfn.QUARTILE.INC(_xlfn._xlws.FILTER(Calycosa!J$2:J1000, Calycosa!J$2:J1000<>""), 1)} -> 0.714 | I23: {=_xlfn.QUARTILE.INC(_xlfn._xlws.FILTER(Calycosa!K$2:K1000, Calycosa!K$2:K1000<>""), 3) - _xlfn.QUARTILE.INC(_xlfn._xlws.FILTER(Calycosa!K$2:K1000, Calycosa!K$2:K1000<>""), 1)} -> 0.405 | J23: {=_xlfn.QUARTILE.INC(_xlfn._xlws.FILTER(Calycosa!L$2:L1000, Calycosa!L$2:L1000<>""), 3) - _xlfn.QUARTILE.INC(_xlfn._xlws.FILTER(Calycosa!L$2:L1000, Calycosa!L$2:L1000<>""), 1)} -> 0.4625 | ... P23: {=_xlfn.QUARTILE.INC(_xlfn._xlws.FILTER(Calycosa!R$2:R1000, Calycosa!R$2:R1000<>""), 3) - _xlfn.QUARTILE.INC(_xlfn._xlws.FILTER(Calycosa!R$2:R1000, Calycosa!R$2:R1000<>""), 1)} -> 217.298
A24: CALYCOSA lower bound outliers | B24: Lower fence | C24: {=_xlfn.QUARTILE.INC(_xlfn._xlws.FILTER(Calycosa!E$2:E1000, Calycosa!E$2:E1000<>""), 1) - 1.5*(_xlfn.QUARTILE.INC(_xlfn._xlws.FILTER(Calycosa!E$2:E1000, Calycosa!E$2:E1000<>""), 3) - _xlfn.QUARTILE.INC(_xlfn._xlws.FILTER(Calycosa!E$2:E1000, Calycosa!E$2:E1000<>""), 1))} -> 0 | D24: {=_xlfn.QUARTILE.INC(_xlfn._xlws.FILTER(Calycosa!F$2:F1000, Calycosa!F$2:F1000<>""), 1) - 1.5*(_xlfn.QUARTILE.INC(_xlfn._xlws.FILTER(Calycosa!F$2:F1000, Calycosa!F$2:F1000<>""), 3) - _xlfn.QUARTILE.INC(_xlfn._xlws.FILTER(Calycosa!F$2:F1000, Calycosa!F$2:F1000<>""), 1))} -> 0 | E24: {=_xlfn.QUARTILE.INC(_xlfn._xlws.FILTER(Calycosa!G$2:G1000, Calycosa!G$2:G1000<>""), 1) - 1.5*(_xlfn.QUARTILE.INC(_xlfn._xlws.FILTER(Calycosa!G$2:G1000, Calycosa!G$2:G1000<>""), 3) - _xlfn.QUARTILE.INC(_xlfn._xlws.FILTER(Calycosa!G$2:G1000, Calycosa!G$2:G1000<>""), 1))} -> 0 | F24: {=_xlfn.QUARTILE.INC(_xlfn._xlws.FILTER(Calycosa!H$2:H1000, Calycosa!H$2:H1000<>""), 1) - 1.5*(_xlfn.QUARTILE.INC(_xlfn._xlws.FILTER(Calycosa!H$2:H1000, Calycosa!H$2:H1000<>""), 3) - _xlfn.QUARTILE.INC(_xlfn._xlws.FILTER(Calycosa!H$2:H1000, Calycosa!H$2:H1000<>""), 1))} -> 2.144375 | G24: {=_xlfn.QUARTILE.INC(_xlfn._xlws.FILTER(Calycosa!I$2:I1000, Calycosa!I$2:I1000<>""), 1) - 1.5*(_xlfn.QUARTILE.INC(_xlfn._xlws.FILTER(Calycosa!I$2:I1000, Calycosa!I$2:I1000<>""), 3) - _xlfn.QUARTILE.INC(_xlfn._xlws.FILTER(Calycosa!I$2:I1000, Calycosa!I$2:I1000<>""), 1))} -> 0.095125 | H24: {=_xlfn.QUARTILE.INC(_xlfn._xlws.FILTER(Calycosa!J$2:J1000, Calycosa!J$2:J1000<>""), 1) - 1.5*(_xlfn.QUARTILE.INC(_xlfn._xlws.FILTER(Calycosa!J$2:J1000, Calycosa!J$2:J1000<>""), 3) - _xlfn.QUARTILE.INC(_xlfn._xlws.FILTER(Calycosa!J$2:J1000, Calycosa!J$2:J1000<>""), 1))} -> 1.605 | I24: {=_xlfn.QUARTILE.INC(_xlfn._xlws.FILTER(Calycosa!K$2:K1000, Calycosa!K$2:K1000<>""), 1) - 1.5*(_xlfn.QUARTILE.INC(_xlfn._xlws.FILTER(Calycosa!K$2:K1000, Calycosa!K$2:K1000<>""), 3) - _xlfn.QUARTILE.INC(_xlfn._xlws.FILTER(Calycosa!K$2:K1000, Calycosa!K$2:K1000<>""), 1))} -> 0.2565 | J24: {=_xlfn.QUARTILE.INC(_xlfn._xlws.FILTER(Calycosa!L$2:L1000, Calycosa!L$2:L1000<>""), 1) - 1.5*(_xlfn.QUARTILE.INC(_xlfn._xlws.FILTER(Calycosa!L$2:L1000, Calycosa!L$2:L1000<>""), 3) - _xlfn.QUARTILE.INC(_xlfn._xlws.FILTER(Calycosa!L$2:L1000, Calycosa!L$2:L1000<>""), 1))} -> -0.0045 | ... P24: {=_xlfn.QUARTILE.INC(_xlfn._xlws.FILTER(Calycosa!R$2:R1000, Calycosa!R$2:R1000<>""), 1) - 1.5*(_xlfn.QUARTILE.INC(_xlfn._xlws.FILTER(Calycosa!R$2:R1000, Calycosa!R$2:R1000<>""), 3) - _xlfn.QUARTILE.INC(_xlfn._xlws.FILTER(Calycosa!R$2:R1000, Calycosa!R$2:R1000<>""), 1))} -> 273.331
A25: CALYCOSA upper bound outliers | B25: Upper fence | C25: {=_xlfn.QUARTILE.INC(_xlfn._xlws.FILTER(Calycosa!E$2:E1000, Calycosa!E$2:E1000<>""), 3) + 1.5*(_xlfn.QUARTILE.INC(_xlfn._xlws.FILTER(Calycosa!E$2:E1000, Calycosa!E$2:E1000<>""), 3) - _xlfn.QUARTILE.INC(_xlfn._xlws.FILTER(Calycosa!E$2:E1000, Calycosa!E$2:E1000<>""), 1))} -> 0 | D25: {=_xlfn.QUARTILE.INC(_xlfn._xlws.FILTER(Calycosa!F$2:F1000, Calycosa!F$2:F1000<>""), 3) + 1.5*(_xlfn.QUARTILE.INC(_xlfn._xlws.FILTER(Calycosa!F$2:F1000, Calycosa!F$2:F1000<>""), 3) - _xlfn.QUARTILE.INC(_xlfn._xlws.FILTER(Calycosa!F$2:F1000, Calycosa!F$2:F1000<>""), 1))} -> 0 | E25: {=_xlfn.QUARTILE.INC(_xlfn._xlws.FILTER(Calycosa!G$2:G1000, Calycosa!G$2:G1000<>""), 3) + 1.5*(_xlfn.QUARTILE.INC(_xlfn._xlws.FILTER(Calycosa!G$2:G1000, Calycosa!G$2:G1000<>""), 3) - _xlfn.QUARTILE.INC(_xlfn._xlws.FILTER(Calycosa!G$2:G1000, Calycosa!G$2:G1000<>""), 1))} -> 0 | F25: {=_xlfn.QUARTILE.INC(_xlfn._xlws.FILTER(Calycosa!H$2:H1000, Calycosa!H$2:H1000<>""), 3) + 1.5*(_xlfn.QUARTILE.INC(_xlfn._xlws.FILTER(Calycosa!H$2:H1000, Calycosa!H$2:H1000<>""), 3) - _xlfn.QUARTILE.INC(_xlfn._xlws.FILTER(Calycosa!H$2:H1000, Calycosa!H$2:H1000<>""), 1))} -> 6.439375 | G25: {=_xlfn.QUARTILE.INC(_xlfn._xlws.FILTER(Calycosa!I$2:I1000, Calycosa!I$2:I1000<>""), 3) + 1.5*(_xlfn.QUARTILE.INC(_xlfn._xlws.FILTER(Calycosa!I$2:I1000, Calycosa!I$2:I1000<>""), 3) - _xlfn.QUARTILE.INC(_xlfn._xlws.FILTER(Calycosa!I$2:I1000, Calycosa!I$2:I1000<>""), 1))} -> 2.882125 | H25: {=_xlfn.QUARTILE.INC(_xlfn._xlws.FILTER(Calycosa!J$2:J1000, Calycosa!J$2:J1000<>""), 3) + 1.5*(_xlfn.QUARTILE.INC(_xlfn._xlws.FILTER(Calycosa!J$2:J1000, Calycosa!J$2:J1000<>""), 3) - _xlfn.QUARTILE.INC(_xlfn._xlws.FILTER(Calycosa!J$2:J1000, Calycosa!J$2:J1000<>""), 1))} -> 4.461 | I25: {=_xlfn.QUARTILE.INC(_xlfn._xlws.FILTER(Calycosa!K$2:K1000, Calycosa!K$2:K1000<>""), 3) + 1.5*(_xlfn.QUARTILE.INC(_xlfn._xlws.FILTER(Calycosa!K$2:K1000, Calycosa!K$2:K1000<>""), 3) - _xlfn.QUARTILE.INC(_xlfn._xlws.FILTER(Calycosa!K$2:K1000, Calycosa!K$2:K1000<>""), 1))} -> 1.8765 | J25: {=_xlfn.QUARTILE.INC(_xlfn._xlws.FILTER(Calycosa!L$2:L1000, Calycosa!L$2:L1000<>""), 3) + 1.5*(_xlfn.QUARTILE.INC(_xlfn._xlws.FILTER(Calycosa!L$2:L1000, Calycosa!L$2:L1000<>""), 3) - _xlfn.QUARTILE.INC(_xlfn._xlws.FILTER(Calycosa!L$2:L1000, Calycosa!L$2:L1000<>""), 1))} -> 1.8455 | ... P25: {=_xlfn.QUARTILE.INC(_xlfn._xlws.FILTER(Calycosa!R$2:R1000, Calycosa!R$2:R1000<>""), 3) + 1.5*(_xlfn.QUARTILE.INC(_xlfn._xlws.FILTER(Calycosa!R$2:R1000, Calycosa!R$2:R1000<>""), 3) - _xlfn.QUARTILE.INC(_xlfn._xlws.FILTER(Calycosa!R$2:R1000, Calycosa!R$2:R1000<>""), 1))} -> 1142.523
A26: CALYCOSA Min (excluding blanks) | B26: Absolute min | C26: {=MIN(_xlfn._xlws.FILTER(Calycosa!E$2:E1000, Calycosa!E$2:E1000<>""))} -> 0 | D26: {=MIN(_xlfn._xlws.FILTER(Calycosa!F$2:F1000, Calycosa!F$2:F1000<>""))} -> 0 | E26: {=MIN(_xlfn._xlws.FILTER(Calycosa!G$2:G1000, Calycosa!G$2:G1000<>""))} -> 0 | F26: {=MIN(_xlfn._xlws.FILTER(Calycosa!H$2:H1000, Calycosa!H$2:H1000<>""))} -> 2.441 | G26: {=MIN(_xlfn._xlws.FILTER(Calycosa!I$2:I1000, Calycosa!I$2:I1000<>""))} -> 0.532 | H26: {=MIN(_xlfn._xlws.FILTER(Calycosa!J$2:J1000, Calycosa!J$2:J1000<>""))} -> 2.143 | I26: {=MIN(_xlfn._xlws.FILTER(Calycosa!K$2:K1000, Calycosa!K$2:K1000<>""))} -> 0.494 | J26: {=MIN(_xlfn._xlws.FILTER(Calycosa!L$2:L1000, Calycosa!L$2:L1000<>""))} -> 0.474 | ... P26: {=MIN(_xlfn._xlws.FILTER(Calycosa!R$2:R1000, Calycosa!R$2:R1000<>""))} -> 481.688
A27: CALYCOSA Max (excluding blanks) | B27: Absolute max | C27: {=MAX(_xlfn._xlws.FILTER(Calycosa!E$2:E1000, Calycosa!E$2:E1000<>""))} -> 0.871 | D27: {=MAX(_xlfn._xlws.FILTER(Calycosa!F$2:F1000, Calycosa!F$2:F1000<>""))} -> 0.479 | E27: {=MAX(_xlfn._xlws.FILTER(Calycosa!G$2:G1000, Calycosa!G$2:G1000<>""))} -> 1.42 | F27: {=MAX(_xlfn._xlws.FILTER(Calycosa!H$2:H1000, Calycosa!H$2:H1000<>""))} -> 8.919 | G27: {=MAX(_xlfn._xlws.FILTER(Calycosa!I$2:I1000, Calycosa!I$2:I1000<>""))} -> 2.55 | H27: {=MAX(_xlfn._xlws.FILTER(Calycosa!J$2:J1000, Calycosa!J$2:J1000<>""))} -> 4.258 | I27: {=MAX(_xlfn._xlws.FILTER(Calycosa!K$2:K1000, Calycosa!K$2:K1000<>""))} -> 1.651 | J27: {=MAX(_xlfn._xlws.FILTER(Calycosa!L$2:L1000, Calycosa!L$2:L1000<>""))} -> 1.612 | ... P27: {=MAX(_xlfn._xlws.FILTER(Calycosa!R$2:R1000, Calycosa!R$2:R1000<>""))} -> 961.619
